2024-02-08 02:59:58,954 INFO    StreamThr :43420 [internal.py:wandb_internal():87] W&B internal server running at pid: 43420, started at: 2024-02-08 02:59:58.954218
2024-02-08 02:59:58,955 DEBUG   HandlerThread:43420 [handler.py:handle_request():144] handle_request: status
2024-02-08 02:59:58,965 INFO    WriterThread:43420 [datastore.py:open_for_write():85] open: C:\Users\ktsui\Project-Build-an-ML-Pipeline-Starter\wandb\run-20240208_025958-re74elpb\run-re74elpb.wandb
2024-02-08 02:59:58,966 DEBUG   SenderThread:43420 [sender.py:send():334] send: header
2024-02-08 02:59:59,002 DEBUG   SenderThread:43420 [sender.py:send():334] send: run
2024-02-08 02:59:59,758 ERROR   SenderThread:43420 [internal_api.py:execute():244] 404 response executing GraphQL.
2024-02-08 02:59:59,759 ERROR   SenderThread:43420 [internal_api.py:execute():245] {"errors":[{"message":"entity ent1 not found during upsertBucket","path":["upsertBucket"]}],"data":{"upsertBucket":null}}
2024-02-08 03:00:00,009 INFO    HandlerThread:43420 [handler.py:finish():841] shutting down handler
2024-02-08 03:00:00,009 INFO    WriterThread:43420 [datastore.py:close():299] close: C:\Users\ktsui\Project-Build-an-ML-Pipeline-Starter\wandb\run-20240208_025958-re74elpb\run-re74elpb.wandb
2024-02-08 03:00:00,009 ERROR   StreamThr :43420 [internal.py:wandb_internal():175] Thread SenderThread:
Traceback (most recent call last):
  File "C:\Users\ktsui\anaconda3\envs\nyc_airbnb_dev\lib\site-packages\wandb\sdk\lib\retry.py", line 128, in __call__
    result = self._call_fn(*args, **kwargs)
  File "C:\Users\ktsui\anaconda3\envs\nyc_airbnb_dev\lib\site-packages\wandb\sdk\internal\internal_api.py", line 241, in execute
    return self.client.execute(*args, **kwargs)  # type: ignore
  File "C:\Users\ktsui\anaconda3\envs\nyc_airbnb_dev\lib\site-packages\wandb\vendor\gql-0.2.0\wandb_gql\client.py", line 52, in execute
    result = self._get_result(document, *args, **kwargs)
  File "C:\Users\ktsui\anaconda3\envs\nyc_airbnb_dev\lib\site-packages\wandb\vendor\gql-0.2.0\wandb_gql\client.py", line 60, in _get_result
    return self.transport.execute(document, *args, **kwargs)
  File "C:\Users\ktsui\anaconda3\envs\nyc_airbnb_dev\lib\site-packages\wandb\vendor\gql-0.2.0\wandb_gql\transport\requests.py", line 39, in execute
    request.raise_for_status()
  File "C:\Users\ktsui\anaconda3\envs\nyc_airbnb_dev\lib\site-packages\requests\models.py", line 1021, in raise_for_status
    raise HTTPError(http_error_msg, response=self)
requests.exceptions.HTTPError: 404 Client Error: Not Found for url: https://api.wandb.ai/graphql

During handling of the above exception, another exception occurred:

Traceback (most recent call last):
  File "C:\Users\ktsui\anaconda3\envs\nyc_airbnb_dev\lib\site-packages\wandb\apis\normalize.py", line 26, in wrapper
    return func(*args, **kwargs)
  File "C:\Users\ktsui\anaconda3\envs\nyc_airbnb_dev\lib\site-packages\wandb\sdk\internal\internal_api.py", line 1592, in upsert_run
    response = self.gql(
  File "C:\Users\ktsui\anaconda3\envs\nyc_airbnb_dev\lib\site-packages\wandb\sdk\internal\internal_api.py", line 213, in gql
    ret = self._retry_gql(
  File "C:\Users\ktsui\anaconda3\envs\nyc_airbnb_dev\lib\site-packages\wandb\sdk\lib\retry.py", line 144, in __call__
    retry_timedelta_triggered = check_retry_fn(e)
  File "C:\Users\ktsui\anaconda3\envs\nyc_airbnb_dev\lib\site-packages\wandb\util.py", line 1065, in check_retry_fn
    return fallback_retry_fn(e)
  File "C:\Users\ktsui\anaconda3\envs\nyc_airbnb_dev\lib\site-packages\wandb\util.py", line 1012, in no_retry_auth
    raise CommError("Permission denied, ask the project owner to grant you access")
wandb.errors.CommError: Permission denied, ask the project owner to grant you access

During handling of the above exception, another exception occurred:

Traceback (most recent call last):
  File "C:\Users\ktsui\anaconda3\envs\nyc_airbnb_dev\lib\site-packages\wandb\sdk\internal\internal_util.py", line 49, in run
    self._run()
  File "C:\Users\ktsui\anaconda3\envs\nyc_airbnb_dev\lib\site-packages\wandb\sdk\internal\internal_util.py", line 100, in _run
    self._process(record)
  File "C:\Users\ktsui\anaconda3\envs\nyc_airbnb_dev\lib\site-packages\wandb\sdk\internal\internal.py", line 329, in _process
    self._sm.send(record)
  File "C:\Users\ktsui\anaconda3\envs\nyc_airbnb_dev\lib\site-packages\wandb\sdk\internal\sender.py", line 341, in send
    send_handler(record)
  File "C:\Users\ktsui\anaconda3\envs\nyc_airbnb_dev\lib\site-packages\wandb\sdk\internal\sender.py", line 927, in send_run
    self._init_run(run, config_value_dict)
  File "C:\Users\ktsui\anaconda3\envs\nyc_airbnb_dev\lib\site-packages\wandb\sdk\internal\sender.py", line 955, in _init_run
    server_run, inserted, server_messages = self._api.upsert_run(
  File "C:\Users\ktsui\anaconda3\envs\nyc_airbnb_dev\lib\site-packages\wandb\apis\normalize.py", line 64, in wrapper
    raise CommError(message, err).with_traceback(sys.exc_info()[2])
  File "C:\Users\ktsui\anaconda3\envs\nyc_airbnb_dev\lib\site-packages\wandb\apis\normalize.py", line 26, in wrapper
    return func(*args, **kwargs)
  File "C:\Users\ktsui\anaconda3\envs\nyc_airbnb_dev\lib\site-packages\wandb\sdk\internal\internal_api.py", line 1592, in upsert_run
    response = self.gql(
  File "C:\Users\ktsui\anaconda3\envs\nyc_airbnb_dev\lib\site-packages\wandb\sdk\internal\internal_api.py", line 213, in gql
    ret = self._retry_gql(
  File "C:\Users\ktsui\anaconda3\envs\nyc_airbnb_dev\lib\site-packages\wandb\sdk\lib\retry.py", line 144, in __call__
    retry_timedelta_triggered = check_retry_fn(e)
  File "C:\Users\ktsui\anaconda3\envs\nyc_airbnb_dev\lib\site-packages\wandb\util.py", line 1065, in check_retry_fn
    return fallback_retry_fn(e)
  File "C:\Users\ktsui\anaconda3\envs\nyc_airbnb_dev\lib\site-packages\wandb\util.py", line 1012, in no_retry_auth
    raise CommError("Permission denied, ask the project owner to grant you access")
wandb.errors.CommError: Permission denied, ask the project owner to grant you access
